Workbook

Sheet Regression Analysis
A1: SUMMARY OUTPUT
A3: Regression Statistics
A4: Multiple R | B4: 0.36021765
A5: R Square | B5: 0.12975675
A6: Adjusted R Square | B6: 0.11475256
A7: Standard Error | B7: 0.082459798
A8: Observations | B8: 60
A10: ANOVA
B11: df | C11: SS | D11: MS | E11: F | F11: Significance F
A12: Regression | B12: 1 | C12: 0.058803318 | D12: 0.058803318 | E12: 8.6480323 | F12: 0.004696889
A13: Residual | B13: 58 | C13: 0.39437786 | D13: 0.0067996182
A14: Total | B14: 59 | C14: 0.45318117
B16: Coefficients | C16: Standard Error | D16: t Stat | E16: P-value | F16: Lower 95% | G16: Upper 95% | H16: Lower 95.0% | I16: Upper 95.0%
A17: Intercept | B17: 0.024186848 | C17: 0.010677901 | D17: 2.2651314 | E17: 0.02725582 | F17: 0.0028127072 | G17: 0.04556099 | H17: 0.0028127072 | I17: 0.04556099
A18: X Variable 1 | B18: 0.65892381 | C18: 0.2240663 | D18: 2.9407537 | E18: 0.004696889 | F18: 0.21040637 | G18: 1.1074412 | H18: 0.21040637 | I18: 1.1074412
C22: Here R square value is 12.98%
C23: Approximately only 13% of TechnologyOne’s return variation is explained by market movements.
C25: Statistical Significance:
C26: p-value = 0.0047 < 0.05
C27: β is statistically significant at 5% level.
C28: β <1 - Hence it is a defensive stock

Sheet Beta
A1: Date | B1: TNE_AdjClose | C1: ASX_AdjClose | D1: TNE Return | E1: ASX Return
A2: 43252 | B2: 3.9576557 | C2: 6194.6001
A3: 43282 | B3: 4.6001925 | C3: 6280.2002 | D3: =(B3-B2)/B2 -> 0.1623529 | E3: =(C3-C2)/C2 -> 0.013818503
A4: 43313 | B4: 5.1496077 | C4: 6319.5 | D4: =(B4-B3)/B3 -> 0.11943307 | E4: =(C4-C3)/C3 -> 0.0062577312
A5: 43344 | B5: 5.1961689 | C5: 6207.6001 | D5: =(B5-B4)/B4 -> 0.0090417065 | E5: =(C5-C4)/C4 -> -0.017707082 | G5: Covariance | H5: =_xlfn.COVARIANCE.S(D3:D62, E3:E62) -> 0.001512567
A6: 43374 | B6: 5.0657983 | C6: 5830.2998 | D6: =(B6-B5)/B5 -> -0.025089757 | E6: =(C6-C5)/C5 -> -0.06078038 | G6: Variance | H6: =_xlfn.VAR.S(E3:E62) -> 0.0022955112
A7: 43405 | B7: 5.8014579 | C7: 5667.2002 | D7: =(B7-B6)/B6 -> 0.14522086 | E7: =(C7-C6)/C6 -> -0.027974481
A8: 43435 | B8: 5.7943091 | C8: 5646.3999 | D8: =(B8-B7)/B7 -> -0.0012322321 | E8: =(C8-C7)/C7 -> -0.0036702944 | G8: β | H8: =H5/H6 -> 0.65892381 | I8: β = Cov(Ri, Rm) / Var(Rm)
A9: 43466 | B9: 6.5562239 | C9: 5864.7002 | D9: =(B9-B8)/B8 -> 0.13149363 | E9: =(C9-C8)/C8 -> 0.038661855
A10: 43497 | B10: 6.9418845 | C10: 6169 | D10: =(B10-B9)/B9 -> 0.058823594 | E10: =(C10-C9)/C9 -> 0.051886677
A11: 43525 | B11: 7.5250778 | C11: 6180.7002 | D11: =(B11-B10)/B10 -> 0.084010804 | E11: =(C11-C10)/C10 -> 0.0018966113
A12: 43556 | B12: 8.2681789 | C12: 6325.5 | D12: =(B12-B11)/B11 -> 0.098749958 | E12: =(C12-C11)/C11 -> 0.023427735
A13: 43586 | B13: 6.7255378 | C13: 6396.8999 | D13: =(B13-B12)/B12 -> -0.18657569 | E13: =(C13-C12)/C12 -> 0.01128763 | H13: SUMMARY OUTPUT
A14: 43617 | B14: 7.4434633 | C14: 6618.7998 | D14: =(B14-B13)/B13 -> 0.10674619 | E14: =(C14-C13)/C13 -> 0.034688663
A15: 43647 | B15: 7.235651 | C15: 6812.6001 | D15: =(B15-B14)/B14 -> -0.027918766 | E15: =(C15-C14)/C14 -> 0.029280277 | H15: Regression Statistics
A16: 43678 | B16: 7.1600833 | C16: 6604.2002 | D16: =(B16-B15)/B15 -> -0.010443804 | E16: =(C16-C15)/C15 -> -0.030590362 | H16: Multiple R | I16: 0.36021765
A17: 43709 | B17: 6.7822423 | C17: 6688.2998 | D17: =(B17-B16)/B16 -> -0.052770475 | E17: =(C17-C16)/C16 -> 0.012734261 | H17: R Square | I17: 0.12975675
A18: 43739 | B18: 6.9617167 | C18: 6663.3999 | D18: =(B18-B17)/B17 -> 0.026462392 | E18: =(C18-C17)/C17 -> -0.0037229046 | H18: Adjusted R Square | I18: 0.11475256
A19: 43770 | B19: 8.680892 | C19: 6846 | D19: =(B19-B18)/B18 -> 0.24694704 | E19: =(C19-C18)/C18 -> 0.027403443 | H19: Standard Error | I19: 0.082459798
A20: 43800 | B20: 7.9066191 | C20: 6684.1001 | D20: =(B20-B19)/B19 -> -0.089192783 | E20: =(C20-C19)/C19 -> -0.023648832 | H20: Observations | I20: 60
A21: 43831 | B21: 8.1259842 | C21: 7017.2002 | D21: =(B21-B20)/B20 -> 0.027744491 | E21: =(C21-C20)/C20 -> 0.049834696
A22: 43862 | B22: 7.4774299 | C22: 6441.2002 | D22: =(B22-B21)/B21 -> -0.079812403 | E22: =(C22-C21)/C21 -> -0.08208402 | H22: ANOVA
A23: 43891 | B23: 7.6300316 | C23: 5076.7998 | D23: =(B23-B22)/B22 -> 0.020408312 | E23: =(C23-C22)/C22 -> -0.21182394 | I23: df | J23: SS | K23: MS | L23: F | M23: Significance F
A24: 43922 | B24: 9.0606632 | C24: 5522.3999 | D24: =(B24-B23)/B23 -> 0.18750009 | E24: =(C24-C23)/C23 -> 0.087771847 | H24: Regression | I24: 1 | J24: 0.058803318 | K24: 0.058803318 | L24: 8.6480323 | M24: 0.004696889
A25: 43952 | B25: 8.7173109 | C25: 5755.7002 | D25: =(B25-B24)/B24 -> -0.037894833 | E25: =(C25-C24)/C24 -> 0.042246179 | H25: Residual | I25: 58 | J25: 0.39437786 | K25: 0.0067996182
A26: 43983 | B26: 8.4159451 | C26: 5897.8999 | D26: =(B26-B25)/B25 -> -0.034570965 | E26: =(C26-C25)/C25 -> 0.024705892 | H26: Total | I26: 59 | J26: 0.45318117
A27: 44013 | B27: 8.0521154 | C27: 5927.7998 | D27: =(B27-B26)/B26 -> -0.043230987 | E27: =(C27-C26)/C26 -> 0.0050695846
A28: 44044 | B28: 7.7361579 | C28: 6060.5 | D28: =(B28-B27)/B27 -> -0.039239073 | E28: =(C28-C27)/C27 -> 0.022386079 | I28: Coefficients | J28: Standard Error | K28: t Stat | L28: P-value | M28: Lower 95% | N28: Upper 95% | O28: Lower 95.0% | P28: Upper 95.0%
A29: 44075 | B29: 7.6021156 | C29: 5815.8999 | D29: =(B29-B28)/B28 -> -0.017326723 | E29: =(C29-C28)/C28 -> -0.040359722 | H29: Intercept | I29: 0.024186848 | J29: 0.010677901 | K29: 2.2651314 | L29: 0.02725582 | M29: 0.0028127072 | N29: 0.04556099 | O29: 0.0028127072 | P29: 0.04556099
A30: 44105 | B30: 8.5882845 | C30: 5927.6001 | D30: =(B30-B29)/B29 -> 0.12972295 | E30: =(C30-C29)/C29 -> 0.019206004 | H30: X Variable 1 | I30: 0.65892381 | J30: 0.2240663 | K30: 2.9407537 | L30: 0.004696889 | M30: 0.21040637 | N30: 1.1074412 | O30: 0.21040637 | P30: 1.1074412
A31: 44136 | B31: 8.7893486 | C31: 6517.7998 | D31: =(B31-B30)/B30 -> 0.02341144 | E31: =(C31-C30)/C30 -> 0.099568071
A32: 44166 | B32: 7.8510523 | C32: 6587.1001 | D32: =(B32-B31)/B31 -> -0.10675379 | E32: =(C32-C31)/C31 -> 0.010632467
A33: 44197 | B33: 8.3489943 | C33: 6607.3999 | D33: =(B33-B32)/B32 -> 0.063423596 | E33: =(C33-C32)/C32 -> 0.0030817514
A34: 44228 | B34: 8.1845284 | C34: 6673.2998 | D34: =(B34-B33)/B33 -> -0.019698888 | E34: =(C34-C33)/C33 -> 0.0099736513
A35: 44256 | B35: 9.0358734 | C35: 6790.7002 | D35: =(B35-B34)/B34 -> 0.10401883 | E35: =(C35-C34)/C34 -> 0.017592555
A36: 44287 | B36: 9.1713142 | C36: 7025.7998 | D36: =(B36-B35)/B35 -> 0.014989235 | E36: =(C36-C35)/C35 -> 0.03462082
A37: 44317 | B37: 8.9004316 | C37: 7161.6001 | D37: =(B37-B36)/B36 -> -0.029535855 | E37: =(C37-C36)/C36 -> 0.019328802 | G37: Statistical Significance:
A38: 44348 | B38: 9.0068521 | C38: 7313 | D38: =(B38-B37)/B37 -> 0.011956782 | E38: =(C38-C37)/C37 -> 0.021140513 | G38: TechnologyOne’s beta is 0.659 and statistically significant (p = 0.0047)
A39: 44378 | B39: 9.1720724 | C39: 7392.6001 | D39: =(B39-B38)/B38 -> 0.018343841 | E39: =(C39-C38)/C38 -> 0.010884739 | G39: The R² of 12.98% indicates that most return variation is firm-specific rather than market-driven, Approximately only 13% return variation is explained by market movements.
A40: 44409 | B40: 9.5995855 | C40: 7534.8999 | D40: =(B40-B39)/B39 -> 0.046610308 | E40: =(C40-C39)/C39 -> 0.019248952 | G40: The regression model is statistically valid (F = 8.65)
...

Sheet WACC
B3: Project Given data | F3: Calculated Data
B4: Given Data | C4: Assumption | D4: Description | F4: Calculated Data | G4: Value | H4: Description
B5: Tax Rate - NZ | C5: 0.28 | D5: Applicable Corporate tax rate | F5: TNE β | G5: =Beta!H8 -> 0.65892381 | H5: Levered beta from regression (ref: Beta tab)
B6: Tax Rate - AU | C6: 0.3 | D6: Unlevering comparable firm beta | F6: D/E | G6: =C7/C8 -> 0.13636364 | H6: Debt-to-equity ratio of TNE
B7: D - TNE | C7: 12 | D7: Debt percentage of TechnologyOne | F7: TNE_ASSET β | G7: =G5/(1+(1-0.3)*G6) -> 0.60150721 | H7: Unlevered beta
B8: E - TNE | C8: 88 | D8: Equity percentage of TechnologyOne | F8: Debt Weight | G8: =C9/(1+C9) -> 0.33333333 | H8: Target capital structure debt weight
B9: Targer D/E | C9: 0.5 | D9: Intended capital structure for RosterLab expansion | F9: Equity Weight | G9: =1/(1+C9) -> 0.66666667 | H9: Target capital structure Equity weight
B10: rF | C10: 0.045 | D10: Risk-Free rate | F10: RosterLab β | G10: =G7*(1+C9*(1-C5)) -> 0.81804981 | H10: Relevered beta for project risk
B11: rM | C11: 0.12 | D11: Market return | F11: rE (Cost of Equity) | G11: =C10+G10*(C11-C10) -> 0.10635374 | H11: Cost of equity from CAPM
B12: rD | C12: 0.1 | D12: Cost of debt for Rooster lab | F12: WACC | G12: =Sensitivity!G21 -> 0.0949 | H12: Weighted average cost of capital
F13: IRR | G13: =IRR(D65:I65) -> 0.15159651 | H13: Internal Rate of return
D14: Formulas Used
D15: TNE β​=Cov(RTNE​,RM​)​/Var(RM​) | E15: =COVARIANCE.S(TNE_returns, Market_returns) / VAR.S(Market_returns)
D16: TNE_ASSET β ​=βE​​/(1+(1−T)*(D/E))​ | E16: =TNE β​/ (1 + (1 - Tax_AU) * (D_TNE / E_TNE))
D17: RosterLab β​=βA​×(1+(1−T)*(D/E)​) | E17: =TNE_ASSET β ​* (1 + (1 - Tax_NZ) * Target_DE)
D18: rE​=rf​+β(rM​−rf​) | E18: =rf + RosterLab β * (rM - rf)
D19: Debt Weight (wD)= Target_DE / (1 + Target_DE)
D20: Equity Weight (wE)=1 / (1 + Target_DE)
D21: WACC=wE​rE​+wD​rD​(1−T) | E21: =Equity_Weight * rE + Debt_Weight * rD * (1 - Tax_NZ)
B27: WACC
B29: Worldwide market | D29: 2000000000 | E29: 2000000000 | F29: =E29*(1+$D$30) -> 2040000000 | G29: =F29*(1+$D$30) -> 2080800000 | H29: =G29*(1+$D$30) -> 2122416000 | I29: =H29*(1+$D$30) -> 2164864320
B30: WW market growth | D30: 0.02
B32: RosterLab market share | E32: =Sensitivity!G10 -> 0.01 | F32: =E32+0.005 -> 0.015 | G32: =F32+0.005 -> 0.02 | H32: =G32+0.005 -> 0.025 | I32: =H32+0.005 -> 0.03
B34: RosterLab Advertising spend | C34: 600000 | D34: Y0
C35: 500000 | D35: Y1
C36: 400000 | D36: Y2
C37: 300000 | D37: Y3
C38: 200000 | D38: Y4
B40: Equipment Cost Y0 | C40: 10000000
B41: Y3 | C41: 1000000
B42: NWC (% Sales) | C42: 0.015 | E42: =E50*$C$42 -> 300000 | F42: =F50*$C$42 -> 459000 | G42: =G50*$C$42 -> 624240 | H42: =H50*$C$42 -> 795906 | I42: =I50*$C$42 -> 974188.94
B43: Depreciation | C43: 0.2 | D43: p.a.
B44: Variable Production Costs | C44: =Sensitivity!G16 -> 0.85 | D44: of revenue
B45: Fixed Production Costs | C45: 1500000 | D45: p.a.
B48: Free Cash Flow to Firm (FCFF) & Discounted Cash Flow(DCF) Model
C49: Period | D49: 0 | E49: 1 | F49: 2 | G49: 3 | H49: 4 | I49: 5
B50: Revenue | E50: =E29*E32 -> 20000000 | F50: =F29*F32 -> 30600000 | G50: =G29*G32 -> 41616000 | H50: =H29*H32 -> 53060400 | I50: =I29*I32 -> 64945930
B51: -Advertising & Marketing | D51: =-C34 -> -600000 | E51: =-C35 -> -500000 | F51: =-C36 -> -400000 | G51: =-C37 -> -300000 | H51: =-C38 -> -200000
B52: -Variable Operating Costs | E52: =-E50*$C$44 -> -17000000 | F52: =-F50*$C$44 -> -26010000 | G52: =-G50*$C$44 -> -35373600 | H52: =-H50*$C$44 -> -45101340 | I52: =-I50*$C$44 -> -55204040
B53: -Fixed Operating Costs | E53: =-C45 -> -1500000 | F53: =E53 -> -1500000 | G53: =F53 -> -1500000 | H53: =G53 -> -1500000 | I53: =H53 -> -1500000
...

Sheet Sensitivity
A1: NPV_Base = | B1: =WACC!C71 -> 2190500.2
A2: Sensitivity Analysis Summary
A4: Variable | B4: Down Case NPV | C4: Base NPV | D4: Up Case NPV | E4: Impact Value | F4: % Impact | G4: Interpretation
A5: Market Share (±1%) | B5: =H12 -> -7792940 | C5: =B1 -> 2190500.2 | D5: =H13 -> 10964124 | E5: =ABS(D5-B5) -> 18757064 | F5: =E5/ B1 -> 8.5629138 | G5: NPV changes by approximately 8.5× the base NPV, indicating high operating sensitivity | BO5: Market Share (±1%) | BP5: =E5 -> 18757064
A6: Variable Cost (±5%) | B6: =C18 -> 7979172 | C6: =B1 -> 2190500.2 | D6: =E18 -> -3794367 | E6: =ABS(D6-B6) -> 11773539 | F6: =E6/C6 -> 5.3748177 | G6: NPV is highly sensitive to variable cost assumptions, with a swing exceeding 5× the base NPV | BO6: Variable Cost (±5%) | BP6: =E6 -> 11773539
A7: WACC (±1%) | B7: =C23 -> 2635679 | C7: =B1 -> 2190500.2 | D7: =E23 -> 1757255 | E7: =ABS(D7-B7) -> 878424 | F7: =ABS(E7/C7) -> 0.40101526 | G7: NPV shows relatively low sensitivity or negative impact to changes in the discount rate. | BO7: WACC (±1%) | BP7: =E7 -> 878424
I9: Input this highlighted cell
F10: Share Stock (Input) | G10: 0.01
A11: Market Share | B11: Base | C11: 0.01 | D11: 0.015 | E11: 0.02 | F11: 0.025 | G11: 0.03 | H11: NPV | I11: Impact
B12: Down Case (-1%) | C12: 0 | D12: =C12+0.5% -> 0.005 | E12: =D12+0.5% -> 0.01 | F12: =E12+0.5% -> 0.015 | G12: =F12+0.5% -> 0.02 | H12: -7792940 | I12: =H13-H12 -> 18757064
B13: Up Case (+1%) | C13: 0.02 | D13: =C13+0.5% -> 0.025 | E13: =D13+0.5% -> 0.03 | F13: =E13+0.5% -> 0.035 | G13: =F13+0.5% -> 0.04 | H13: 10964124
F16: Variable Operating Cost | G16: 0.85
A17: Variable Operating Cost | B17: 0.75 | C17: 0.8 | D17: 0.85 | E17: 0.9 | F17: 0.95 | G17: Impact (+_5%)
B18: 13512113 | C18: 7979172 | D18: 2190500 | E18: -3794367 | F18: -10742478 | G18: =C18-E18 -> 11773539
F21: WACC (Input here) | G21: 0.0949
A22: WACC | B22: 0.075 | C22: 0.085 | D22: 0.095 | E22: 0.105 | F22: 0.115 | G22: Impact (+_1%)
B23: 3107213 | C23: 2635679 | D23: 2190500 | E23: 1757255 | F23: 1347954 | G23: =C23-E23 -> 878424
A27: Sensitivity Conclusion
A29: • The project is most sensitive to variable cost assumptions.
A30: • Revenue (market share) assumptions also materially affect value.
A31: • Discount rate changes have relatively lower impact/no impact on positive side.
A33: Therefore, operational execution risk dominates financing risk.
